{
	"document_title": "CVE-2024-32879",
	"document_type": "SUSE CVE",
	"document_publisher": {
		"type": "Vendor",
		"contact_details": "security@suse.de",
		"issuing_authority": "SUSE Security Team"
	},
	"document_tracking": {
		"identification": {
			"id": "SUSE CVE-2024-32879"
		},
		"status": "Interim",
		"version": "1",
		"revision_history": {
			"revision": {
				"number": "2",
				"date": "2024-06-10T23:10:05Z",
				"description": "current"
			}
		},
		"initial_release_date": "2024-04-26T23:08:54Z",
		"current_release_date": "2024-06-10T23:10:05Z",
		"generator": {
			"engine": "cve-database/bin/generate-cvrf-cve.pl",
			"date": "2020-12-27T01:00:00Z"
		}
	},
	"document_notes": [
		{
			"text": "CVE-2024-32879",
			"title": "CVE",
			"type": "Summary"
		},
		{
			"text": "Python Social Auth is a social authentication/registration mechanism. Prior to version 5.4.1, due to default case-insensitive collation in MySQL or MariaDB databases, third-party authentication user IDs are not case-sensitive and could cause different IDs to match. This issue has been addressed by a fix released in version 5.4.1. An immediate workaround would be to change collation of the affected field.",
			"title": "Mitre CVE Description",
			"type": "Description"
		},
		{
			"text": "The CVRF data is provided by SUSE under the Creative Commons License 4.0 with Attribution (CC-BY-4.0).",
			"title": "Terms of Use",
			"type": "Legal Disclaimer"
		}
	],
	"document_references": [
		{
			"type": "Self",
			"url": "https://www.suse.com/support/security/rating/",
			"description": "SUSE Security Ratings"
		}
	],
	"product_tree": {
		"branch": [
			{
				"type": "Product Family",
				"name": "openSUSE Tumbleweed",
				"branch": [
					{
						"type": "Product Name",
						"name": "openSUSE Tumbleweed",
						"full_product_name": {
							"text": "openSUSE Tumbleweed",
							"product_id": "openSUSE Tumbleweed",
							"cpe": "cpe:/o:opensuse:tumbleweed"
						}
					}
				],
				"full_product_name": {}
			},
			{
				"type": "Product Version",
				"name": "python310-social-auth-app-django-5.4.1-1.1",
				"full_product_name": {
					"text": "python310-social-auth-app-django-5.4.1-1.1",
					"product_id": "python310-social-auth-app-django-5.4.1-1.1"
				}
			},
			{
				"type": "Product Version",
				"name": "python311-social-auth-app-django-5.4.1-1.1",
				"full_product_name": {
					"text": "python311-social-auth-app-django-5.4.1-1.1",
					"product_id": "python311-social-auth-app-django-5.4.1-1.1"
				}
			},
			{
				"type": "Product Version",
				"name": "python312-social-auth-app-django-5.4.1-1.1",
				"full_product_name": {
					"text": "python312-social-auth-app-django-5.4.1-1.1",
					"product_id": "python312-social-auth-app-django-5.4.1-1.1"
				}
			}
		],
		"relationship": [
			{
				"product_reference": "python310-social-auth-app-django-5.4.1-1.1",
				"relation_type": "Default Component Of",
				"relates_to_product_reference": "openSUSE Tumbleweed"
			},
			{
				"product_reference": "python311-social-auth-app-django-5.4.1-1.1",
				"relation_type": "Default Component Of",
				"relates_to_product_reference": "openSUSE Tumbleweed"
			},
			{
				"product_reference": "python312-social-auth-app-django-5.4.1-1.1",
				"relation_type": "Default Component Of",
				"relates_to_product_reference": "openSUSE Tumbleweed"
			}
		]
	},
	"vulnerability": [
		{
			"notes": [
				{
					"text": "Python Social Auth is a social authentication/registration mechanism. Prior to version 5.4.1, due to default case-insensitive collation in MySQL or MariaDB databases, third-party authentication user IDs are not case-sensitive and could cause different IDs to match. This issue has been addressed by a fix released in version 5.4.1. An immediate workaround would be to change collation of the affected field.",
					"title": "Vulnerability Description",
					"type": "General"
				}
			],
			"cve": "CVE-2024-32879",
			"product_statuses": [
				{
					"type": "Fixed",
					"product_id": [
						"openSUSE Tumbleweed:python310-social-auth-app-django-5.4.1-1.1",
						"openSUSE Tumbleweed:python311-social-auth-app-django-5.4.1-1.1",
						"openSUSE Tumbleweed:python312-social-auth-app-django-5.4.1-1.1"
					]
				}
			],
			"threats": [
				{
					"type": "Impact",
					"description": "moderate"
				}
			],
			"cvss_score_sets": {
				"score_set_v_2": {},
				"score_set_v_3": {}
			}
		}
	]
}
